<?xml version='1.0'?>
<robot name="skid_clover" xmlns:xacro="http://www.ros.org/wiki/xacro">

<!-- Import all Gazebo-customization elements, including Gazebo colors -->
  <xacro:include filename="$(find clover_odometry)/urdf/skid_clover.gazebo" />


  <xacro:property name="wheel_kp" value="1000000.0" />
  <xacro:property name="wheel_kd" value="100.0" />
  <xacro:property name="wheel_mu1" value="1" />
  <xacro:property name="wheel_mu2" value="1" />
  <xacro:property name="wheel_slip1" value="0.5" />
  <xacro:property name="wheel_slip2" value="0" />

  <link name="robot_footprint">
  </link>

  <joint name="robot_footprint_joint" type="fixed">
    <origin xyz="0 0 0.10" rpy="0 0 0" />
    <parent link="robot_footprint" />
    <child link="base_link" />
  </joint>

  <!-- Base Link -->
  <link name="base_link">
    <visual>
      <origin xyz="0 0 0" rpy="0 0 0" />
      <geometry>
          <box size="0.3 0.3 0.1"/>
      </geometry>
      <material name="lightgrey">
	<color rgba="217 217 217 0.7"/>
      </material>
    </visual>
    <!-- Base collision -->
    <collision>
      <origin xyz="0 0 0" rpy="0 0 0" />
      <geometry>
          <box size="0.3 0.3 0.1"/>
      </geometry>
    </collision>
    <!-- Mass and Inertia -->
    <inertial>
	<mass value='5'/>
	<inertia ixx="0.13" ixy="0.0" ixz="0.0"
		 iyy="0.21" iyz="0.0" izz="0.13"/>
    </inertial>

  </link>




  <!-- Right Front Wheel -->
  <link name="right_front_wheel">
    <visual>
      <origin xyz="0 0 0" rpy="1.570795 0 0" />
      <geometry>
          <cylinder length="0.03" radius="0.10" />
      </geometry>
      <material name="blue">
	<color rgba="0.22 0.7 1 1"/>
      </material>
    </visual>
  <!-- Right Front Wheel collision -->
  <collision>
      <origin xyz="0 0 0" rpy="1.570795 0 0" />
      <geometry>
          <cylinder length="0.03" radius="0.10" />
      </geometry>
      <surface>
        <friction>
          <fdir1>1 0 0</fdir1>
          <kp>${wheel_kp}</kp> <!-- kp and kd for rubber -->
          <kd>${wheel_kd}</kd>
          <mu>${wheel_mu1}</mu>
          <mu2>${wheel_mu2}</mu2>
          <slip1>${wheel_slip1}</slip1>
          <slip2>${wheel_slip2}</slip2>
        </friction>
      </surface>
    </collision>
  <!-- Mass and Inertia -->
  <inertial>
	<mass value='0.5'/>
	<inertia ixx="0.00155" ixy="0.0" ixz="0.0"
		 iyy="0.00155" iyz="0.0" izz="0.003"/>
  </inertial>
  </link>



  <joint name="front_right_wheel_joint" type="continuous">
    <parent link="base_link"/>
    <child link="right_front_wheel"/>
    <origin xyz="0.11 -0.14 0" rpy="0 0 0" />
    <axis xyz="0 1 0" />
    <limit effort="10000" velocity="1000"/>
    <joint_properties damping="1.0" friction="1.0"/>
  </joint>

<transmission name="right_side_transmission">
	<type>transmission_interface/SimpleTransmittion</type>
	<joint name="front_right_wheel_joint">
	  <hardwareInterface>hardware_interface/EffortJointInterface</hardwareInterface>
	</joint>
	<actuator name="right_motor">
	  <hardwareInterface>hardware_interface/EffortJointInterface</hardwareInterface>
	</actuator>
</transmission>





  <!-- Left Front Wheel -->
  <link name="left_front_wheel">
    <visual>
      <origin xyz="0 0 0" rpy="1.570795 0 0" />
      <geometry>
          <cylinder length="0.03" radius="0.10" />
      </geometry>
      <material name="blue"/>
    </visual>
  <!-- Left Front Wheel collision -->
  <collision>
      <origin xyz="0 0 0" rpy="1.570795 0 0" />
      <geometry>
          <cylinder length="0.03" radius="0.10" />
      </geometry>
      <surface>
        <friction>
          <fdir1>1 0 0</fdir1>
          <kp>${wheel_kp}</kp> <!-- kp and kd for rubber -->
          <kd>${wheel_kd}</kd>
          <mu>${wheel_mu1}</mu>
          <mu2>${wheel_mu2}</mu2>
          <slip1>${wheel_slip1}</slip1>
          <slip2>${wheel_slip2}</slip2>
        </friction>
      </surface>
    </collision>
  <!-- Mass and Inertia -->
  <inertial>
	<mass value='0.5'/>
	<inertia ixx="0.00155" ixy="0.0" ixz="0.0"
		 iyy="0.00155" iyz="0.0" izz="0.003"/>
  </inertial>
  </link>


  <joint name="front_left_wheel_joint" type="continuous">
    <parent link="base_link"/>
    <child link="left_front_wheel"/>
    <origin xyz="0.11 0.14 0" rpy="0 0 0" />
    <axis xyz="0 1 0" />
    <limit effort="10000" velocity="1000"/>
    <joint_properties damping="1.0" friction="1.0"/>
  </joint>


<transmission name="leftmotortransm">
	<type>transmission_interface/SimpleTransmittion</type>
	<joint name="front_left_wheel_joint">
	  <hardwareInterface>hardware_interface/EffortJointInterface</hardwareInterface>
	</joint>
	<actuator name="left_motor">
	  <hardwareInterface>hardware_interface/EffortJointInterface</hardwareInterface>
	</actuator>
</transmission>



<!-- Right Rear Wheel -->
  <link name="right_rear_wheel">
    <visual>
      <origin xyz="0 0 0" rpy="1.570795 0 0" />
      <geometry>
          <cylinder length="0.03" radius="0.10" />
      </geometry>
      <material name="blue"/>
    </visual>
  <!-- Right Rear Wheel collision -->
  <collision>
      <origin xyz="0 0 0" rpy="1.570795 0 0" />
      <geometry>
          <cylinder length="0.03" radius="0.10" />
      </geometry>
      <surface>
        <friction>
          <fdir1>1 0 0</fdir1>
          <kp>${wheel_kp}</kp> <!-- kp and kd for rubber -->
          <kd>${wheel_kd}</kd>
          <mu>${wheel_mu1}</mu>
          <mu2>${wheel_mu2}</mu2>
          <slip1>${wheel_slip1}</slip1>
          <slip2>${wheel_slip2}</slip2>
        </friction>
      </surface>
    </collision>
  <!-- Mass and Inertia -->
  <inertial>
	<mass value='0.5'/>
	<inertia ixx="0.00155" ixy="0.0" ixz="0.0"
		 iyy="0.00155" iyz="0.0" izz="0.003"/>
  </inertial>
  </link>

  <joint name="back_right_wheel_joint" type="continuous">
    <parent link="base_link"/>
    <child link="right_rear_wheel"/>
    <origin xyz="-0.11 -0.14 0" rpy="0 0 0" />
    <axis xyz="0 1 0" />
    <limit effort="10000" velocity="1000"/>
    <joint_properties damping="1.0" friction="1.0"/>
  </joint>

  <!-- Left Rear Wheel -->
  <link name="left_rear_wheel">
    <visual>
      <origin xyz="0 0 0" rpy="1.570795 0 0" />
      <geometry>
          <cylinder length="0.03" radius="0.10" />
      </geometry>
      <material name="blue"/>
    </visual>
  <!-- Left Rear Wheel collision -->
  <collision>
      <origin xyz="0 0 0" rpy="1.570795 0 0" />
      <geometry>
          <cylinder length="0.03" radius="0.10" />
      </geometry>
      <surface>
        <friction>
          <fdir1>1 0 0</fdir1>
          <kp>${wheel_kp}</kp> <!-- kp and kd for rubber -->
          <kd>${wheel_kd}</kd>
          <mu>${wheel_mu1}</mu>
          <mu2>${wheel_mu2}</mu2>
          <slip1>${wheel_slip1}</slip1>
          <slip2>${wheel_slip2}</slip2>
        </friction>
      </surface>
    </collision>
  <!-- Mass and Inertia -->
  <inertial>
	<mass value='0.5'/>
	<inertia ixx="0.00155" ixy="0.0" ixz="0.0"
		 iyy="0.00155" iyz="0.0" izz="0.003"/>
  </inertial>

  </link>

  <joint name="back_left_wheel_joint" type="continuous">
    <parent link="base_link"/>
    <child link="left_rear_wheel"/>
    <origin xyz="-0.11 0.14 0" rpy="0 0 0" />
    <axis xyz="0 1 0" />
    <limit effort="10000" velocity="1000"/>
    <joint_properties damping="1.0" friction="1.0"/>
  </joint>


<!-- LIDAR module base -->
  <link name="LIDAR_module_base">
    <visual>
      <origin xyz="0 0 0.125" rpy="0 0 0" />
      <geometry>
          <box size="0.06 0.17 0.15"/>
      </geometry>
      <material name="lightgrey"/>
    </visual>
  <!-- LIDAR module base collision-->
  <collision>
      <origin xyz="0 0 0.125" rpy="0 0 0" />
      <geometry>
          <box size="0.06 0.17 0.15"/>
      </geometry>
    </collision>
  <!-- Mass and Inertia -->
    <inertial>
	<mass value='0.1'/>
	<inertia ixx="0.1" ixy="0.0" ixz="0.0"
		 iyy="0.1" iyz="0.0" izz="0.1"/>
    </inertial>
  </link>


  <joint name="LIDAR_module_base" type="fixed">
    <parent link="base_link"/>
    <child link="LIDAR_module_base"/>
    <origin xyz="0.13 0 0" rpy="0 0 0" />
  </joint>


  <!-- LIDAR module -->
  <link name="hokuyo">
    <visual>
      <origin xyz="0 0 0.055" rpy="0 0 0" />
      <geometry>
          <cylinder length="0.11" radius="0.03" />
      </geometry>
      <material name="black">
	<color rgba="0 0 0 1"/>
      </material>
    </visual>
  <!-- LIDAR module collision
    <collision>
      <origin xyz="0 0 0.055" rpy="0 0 0" />
      <geometry>
          <cylinder length="0.11" radius="0.03" />
      </geometry>
    </collision>
  -->
  <!-- Mass and Inertia -->
    <inertial>
	<mass value='0.4'/>
	<inertia ixx="0.001" ixy="0.0" ixz="0.0"
		 iyy="0.001" iyz="0.0" izz="0.001"/>
    </inertial>

  </link>

  <joint name="hokuyo_joint" type="fixed">
    <parent link="LIDAR_module_base"/>
    <child link="hokuyo"/>
    <origin xyz="0 0 0.2" rpy="0 0 0" />
    <axis xyz="0 0 1" />
    <limit effort="10000" velocity="1000"/>
    <joint_properties damping="1.0" friction="1.0"/>
  </joint>

<!-- camera -->
<link name='camera'>
    <inertial>
      <mass value="0.1"/>
      <origin xyz="0 0 0" rpy=" 0 0 0"/>
      <inertia
          ixx="1e-6" ixy="0" ixz="0"
          iyy="1e-6" iyz="0"
          izz="1e-6"/>
    </inertial>
    <collision name='camera_collision'>
      <origin xyz="0 0 0" rpy=" 0 0 0"/>
      <geometry>
        <box size="0.03 0.1 0.02"/>
      </geometry>
    </collision>
    <visual name='camera_visual'>
      <origin xyz="0 0 0" rpy=" 0 0 0"/>
      <geometry>
        <box size="0.03 0.1 0.02"/>
      </geometry>
    </visual>
  </link>

  <joint type="fixed" name="camera_joint">
    <origin xyz="0.15 0 0" rpy="0 0 0"/>
    <child link="camera"/>
    <parent link="base_link"/>
    <axis xyz="0 1 0" rpy="0 0 0"/>
    <limit effort="10000" velocity="1000"/>
    <joint_properties damping="1.0" friction="1.0"/>
  </joint>




<!-- hokuyo -->

<!--

<gazebo reference="hokuyo">
    <sensor type="ray" name="head_hokuyo_sensor">
      <pose>0 0 0 0 0 0</pose>
      <visualize>false</visualize>
      <update_rate>40</update_rate>
      <ray>
        <scan>
          <horizontal>
            <samples>720</samples>
            <resolution>0.25</resolution>
            <min_angle>-2.38</min_angle>
            <max_angle>2.38</max_angle>
          </horizontal>
        </scan>
        <range>
          <min>0.1</min>
          <max>30.0</max>
          <resolution>0.03</resolution>
        </range>
        <noise>
          <type>gaussian</type>

-->
          <!-- Noise parameters based on published spec for Hokuyo laser
               achieving "+-30mm" accuracy at range < 10m.  A mean of 0.0m and
               stddev of 0.01m will put 99.7% of samples within 0.03m of the true
               reading. -->

<!--
          <mean>0.0</mean>
          <stddev>0.01</stddev>
        </noise>
      </ray>
      <plugin name="gazebo_ros_head_hokuyo_controller" filename="libgazebo_ros_laser.so">
        <topicName>/skid_clover/laser/scan</topicName>
        <frameName>hokuyo</frameName>
      </plugin>
    </sensor>
  </gazebo>

-->

  <gazebo reference="camera">
    <material>Gazebo/Grey</material>
    <sensor type="camera" name="camera1">
      <update_rate>30.0</update_rate>
      <camera name="head">
        <horizontal_fov>1.3962634</horizontal_fov>
        <image>
          <width>800</width>
          <height>800</height>
          <format>R8G8B8</format>
        </image>
        <clip>
          <near>0.02</near>
          <far>300</far>
        </clip>
      </camera>
      <plugin name="camera_controller" filename="libgazebo_ros_camera.so">
        <alwaysOn>true</alwaysOn>
        <updateRate>0.0</updateRate>
        <cameraName>skid_clover/camera1</cameraName>
        <imageTopicName>image_raw</imageTopicName>
        <cameraInfoTopicName>camera_info</cameraInfoTopicName>
        <frameName>camera</frameName>
        <hackBaseline>0.07</hackBaseline>
        <distortionK1>0.0</distortionK1>
        <distortionK2>0.0</distortionK2>
        <distortionK3>0.0</distortionK3>
        <distortionT1>0.0</distortionT1>
        <distortionT2>0.0</distortionT2>
      </plugin>
    </sensor>
  </gazebo>

<!--
<transmission name="lidartransm">
	<type>transmission_interface/SimpleTransmittion</type>
	<joint name="LIDAR_module">
		<hardwareInterface>EffortJointInterface</hardwareInterface>
	</joint>
	<actuator name="LIDARservo">
	</actuator>
</transmission>
-->

  <gazebo>
    <plugin name="gazebo_ros_control" filename="libgazebo_ros_control.so">
    </plugin>
  </gazebo>

<!-- Plugins -->




<!-- Control drive plugin -->
<gazebo>
  <plugin name="skid_steer_drive_controller" filename="libgazebo_ros_skid_steer_drive.so">
    <updateRate>100</updateRate>
    <robotNamespace>/</robotNamespace>
    <leftFrontJoint>front_left_wheel_joint</leftFrontJoint>
    <rightFrontJoint>front_right_wheel_joint</rightFrontJoint>
    <leftRearJoint>back_left_wheel_joint</leftRearJoint>
    <rightRearJoint>back_right_wheel_joint</rightRearJoint>
    <wheelSeparation>0.3</wheelSeparation>
    <wheelDiameter>0.11</wheelDiameter>
    <robotBaseFrame>robot_footprint</robotBaseFrame>
    <torque>40</torque>
    <commandTopic>cmd_vel</commandTopic>
    <odometryTopic>odom</odometryTopic>
    <odometryFrame>odom</odometryFrame>
    <broadcastTF>true</broadcastTF>
    <covariance_x>0.001</covariance_x> <!-- 0.0001 -->
    <covariance_y>0.001</covariance_y> <!-- 0.0001 -->
    <covariance_yaw>0.01</covariance_yaw> <!-- 0.01 -->
  </plugin>
</gazebo>







</robot>
